Workbook

Sheet Overview
A1: AI-Enabled Quality Engineer - 5-Week Plan & Tracker
A2: Manual QA -> AI-Enabled QA. 25 working days. Edit only the BLUE cells.
A4: Start date (Monday) | B4: 46300 | C4: INPUT - first working day. All planned dates recalculate (Mon-Fri).
A5: Study hours per day | B5: 3 | C5: INPUT - assumption: 3 hrs/day alongside a job. Change to your reality.
A6: Programming language | B6: Python | C6: Assumption: Python for scripts/pytest/Playwright. TypeScript works too, but pick ONE and stay with it.
A7: Planned end date | B7: =WORKDAY(B4,24) -> 46332 | C7: Formula - day 25 of the plan.
A8: Overall completion | B8: =Dashboard!D10 -> 0.24 | C8: Formula - from Dashboard.
A10: Prerequisites (you already have these)
A11: Manual testing basics: smoke, sanity, regression, boundary value analysis, equivalence partitioning, risk-based testing.
A13: How to use this workbook
A14: 1. Set Start date and Hours/day above.
A15: 2. '5-Week Plan' = what to learn + exercises + deliverable + capstone increment for each day.
A16: 3. Daily: update 'Tracker' (Status, Actual start, Actual hrs, Evidence link, Confidence, Notes). 'Dashboard' updates itself.
A17: 4. 'Capstone' = the reusable QA-Copilot project you build a piece of every week. 'Portfolio' = your 3 GitHub projects + capstone checklist.
A18: 5. 'Skills' = rate yourself 1-5 now (Before) and at the end (After). 'Learn From' = where to study each day's topic; 'Practice Sites' = demo apps/APIs to practise on.
A19: Rule: AI output is a draft. Every AI-generated test case, code, or bug must be reviewed by you (use your checklist from Day 12).
A21: Weekly themes
A22: Week 1 - Code Like a Tester
A23: Week 2 - Automate (without AI first)
... A26: Week 5 - Test AI Systems + Capstone

Sheet 5-Week Plan
A1: Day-by-day plan with exercises
A2: Planned date = WORKDAY(Overview start date). Each day ~ hours set on Overview.
A3: Day # | B3: Week | C3: Planned date | D3: Topic | E3: Learning objectives | F3: Where to learn first (free, ~1 hr) | G3: Hands-on exercises | H3: Deliverable (evidence) | I3: Capstone increment (QA-Copilot) | J3: Tools
A4: 1 | B4: 1 | C4: =WORKDAY(Overview!$B$4,A4-1) -> 46300 | D4: Dev setup + Git & GitHub | E4: Install Python 3.11+, VS Code, Git. Init/clone, branch, commit, push, PR, merge, resolve conflicts. | F4: 1. Pro Git book - ch.1-3 (basics, branching) [Book/docs, ~60 min] https://git-scm.com/book/en/v2 2. GitHub Skills - Introduction to GitHub (hands-on) [Interactive, ~30 min] https://skills.github.com 3. GitHub Docs - Get started [Docs, ~20 min] https://docs.github.com/en/get-started | G4: 1) Create repo 'ai-qa-journey'. 2) Branch -> add README -> open PR -> merge. 3) Create a deliberate merge conflict and resolve it. 4) Add .gitignore and .env.example (never commit secrets). | H4: Repo link with 5+ commits and 1 merged PR | I4: Create 'qa-copilot' repo skeleton: README, /core /runner /prompts /samples /tests | J4: Git, GitHub, VS Code, Python
A5: 2 | B5: 1 | C5: =WORKDAY(Overview!$B$4,A5-1) -> 46301 | D5: Python core for testers | E5: Variables, lists/dicts, loops, conditionals, functions, exceptions, simple asserts. | F5: 1. Automate the Boring Stuff - Python basics ch.1-6 [Free book, ~90 min] https://automatetheboringstuff.com 2. Official Python Tutorial (loops, functions, errors) [Docs, ~45 min] https://docs.python.org/3/tutorial/ 3. Real Python - beginner articles [Articles, ~30 min] https://realpython.com | G5: 1) Write boundary_values(min,max) returning the 6 BVA values. 2) Write partition(age) -> equivalence class for a ticket-pricing rule. 3) Loop over 20 mock results and print a pass/fail summary. 4) Add 5 assert-based self-checks. | H5: bva.py + ep.py with self-checks | I5: core/techniques.py - BVA/EP helpers (later used to validate AI-generated cases) | J5: Python, VS Code
A6: 3 | B6: 1 | C6: =WORKDAY(Overview!$B$4,A6-1) -> 46302 | D6: Python OOP, files, JSON/CSV | E6: Classes/dataclasses, reading and writing CSV/JSON, basic error handling, JSON Schema idea. | F6: 1. Python docs - dataclasses [Docs, ~30 min] https://docs.python.org/3/library/dataclasses.html 2. Python docs - json and csv modules [Docs, ~30 min] https://docs.python.org/3/library/json.html 3. Pydantic - getting started [Docs, ~30 min] https://docs.pydantic.dev 4. JSON Schema - Learn [Docs, ~30 min] https://json-schema.org/learn | G6: 1) Create dataclass TestCase(id,title,preconditions,steps,expected,priority,type). 2) Read/write CSV and JSON. 3) Load 10 of your own (sanitised) manual test cases into objects and export to JSON. | H6: testcase.py + sample CSV/JSON | I6: Define the canonical TestCase JSON Schema - the contract every module uses | J6: Python, pydantic/jsonschema
A7: 4 | B7: 1 | C7: =WORKDAY(Overview!$B$4,A7-1) -> 46303 | D7: SQL for testers | E7: SELECT/WHERE, JOINs, GROUP BY/HAVING, subqueries, NULL handling, duplicates/orphans. | F7: 1. SQLBolt - interactive SQL lessons 1-18 [Interactive, ~90 min] https://sqlbolt.com 2. SQLite - SQL language reference [Docs, ~20 min] https://sqlite.org/lang.html 3. Chinook sample database (practice data) [Dataset, ~15 min] https://github.com/lerocha/chinook-database 4. SQLZoo - extra practice [Interactive, ~45 min] https://sqlzoo.net | G7: On SQLite (sample orders DB): 1) 12 queries incl. a 3-table JOIN and a GROUP BY/HAVING. 2) Write 5 data-validation checks (e.g. order total <> sum of items, orphan rows, duplicate emails). 3) Run them from Python using sqlite3. | H7: sql_exercises.sql + run_checks.py | I7: Add SQLite results store (results.db) for test runs | J7: SQLite, DB Browser, Python
A8: 5 | B8: 1 | C8: =WORKDAY(Overview!$B$4,A8-1) -> 46304 | D8: HTTP/REST + Postman | E8: Methods, status codes, headers, auth, JSON bodies, Postman variables and test scripts. | F8: 1. Postman Learning Center - 'Postman 101' [Docs/Video, ~60 min] https://learning.postman.com 2. MDN - HTTP overview, methods, status codes [Docs, ~45 min] https://developer.mozilla.org/en-US/docs/Web/HTTP 3. Restful-Booker API docs (your practice API) [API docs, ~15 min] https://restful-booker.herokuapp.com/apidoc/index.html | G8: On Restful-Booker: 1) Collection: auth token, create/get/update/delete booking. 2) Env variables + test scripts (status, schema, response time). 3) Negative tests: 401/404/400. 4) Run with Collection Runner, export JSON. End of week: fill the Week-1 self-rating in the Skills sheet. | H8: Postman collection JSON committed to repo | I8: Save collection under /samples/postman | J8: Postman, restful-booker.herokuapp.com
A9: 6 | B9: 2 | C9: =WORKDAY(Overview!$B$4,A9-1) -> 46307 | D9: API automation: Python requests + pytest | E9: Translate manual API checks into code; fixtures; assertions. | F9: 1. Requests - Quickstart [Docs, ~30 min] https://requests.readthedocs.io 2. pytest - Get started + fixtures [Docs, ~60 min] https://docs.pytest.org 3. Real Python - Effective testing with pytest [Article, ~30 min] https://realpython.com/pytest-python-testing/ | G9: 1) Port your Postman collection to pytest (8+ tests). 2) Session fixture for auth token. 3) Parametrize BVA values for booking fields. 4) Add 4 negative tests. | H9: api-tests/ folder running locally | I9: runner/ module: executes pytest and parses JUnit/JSON results | J9: pytest, requests
A10: 7 | B10: 2 | C10: =WORKDAY(Overview!$B$4,A10-1) -> 46308 | D10: pytest advanced + data-driven | E10: Markers, conftest, parametrize from CSV, schema validation, reports, flaky handling. | F10: 1. pytest - How to parametrize [Docs, ~30 min] https://docs.pytest.org/en/stable/how-to/parametrize.html 2. jsonschema validation in Python [Docs, ~20 min] https://python-jsonschema.readthedocs.io 3. Allure Report docs [Docs, ~30 min] https://allurereport.org/docs/ 4. pytest-html [Docs, ~15 min] https://pytest-html.readthedocs.io | G10: 1) Data-drive tests from your Week-1 CSV. 2) Validate responses with jsonschema/pydantic. 3) Markers: smoke, regression. 4) Generate HTML/Allure report; add rerunfailures for flaky. | H10: API suite with smoke+regression markers and HTML report (PROJECT B ready) | I10: Runner outputs normalised result JSON (pass/fail/error/trace path) | J10: pytest-html, allure, jsonschema
A11: 8 | B11: 2 | C11: =WORKDAY(Overview!$B$4,A11-1) -> 46309 | D11: Playwright basics | E11: Install, role/label/test-id locators, auto-wait, expect assertions, codegen, trace viewer. | F11: 1. Playwright Python - Getting started [Docs, ~45 min] https://playwright.dev/python/docs/intro 2. Playwright - Locators [Docs, ~30 min] https://playwright.dev/python/docs/locators 3. Playwright - Trace Viewer [Docs, ~20 min] https://playwright.dev/python/docs/trace-viewer 4. Playwright - Codegen [Docs, ~15 min] https://playwright.dev/python/docs/codegen | G11: On saucedemo.com: 1) Tests: valid/invalid login, add to cart, checkout. 2) Use getByRole/getByTestId, no sleeps. 3) Record with codegen then clean it up. 4) Force a failure and debug with Trace Viewer. | H11: 8+ Playwright tests passing | I11: Playwright runner adapter in runner/ | J11: Playwright (Python), codegen, trace viewer
A12: 9 | B12: 2 | C12: =WORKDAY(Overview!$B$4,A12-1) -> 46310 | D12: Playwright framework design | E12: Page Object Model, fixtures, storage_state, API+UI hybrid, parallel runs, env config. | F12: 1. Playwright - Page Object Models [Docs, ~30 min] https://playwright.dev/python/docs/pom 2. Playwright - Authentication (storage_state) [Docs, ~20 min] https://playwright.dev/python/docs/auth 3. Playwright - API testing [Docs, ~30 min] https://playwright.dev/python/docs/api-testing | G12: 1) Refactor to POM (LoginPage, InventoryPage, CartPage). 2) Reuse login via storage_state. 3) Create test data through API, verify through UI. 4) Screenshots/video on failure, run in parallel. | H12: Refactored UI framework (PROJECT A) | I12: Define coding conventions to feed into CLAUDE.md later | J12: Playwright, pytest-playwright
A13: 10 | B13: 2 | C13: =WORKDAY(Overview!$B$4,A13-1) -> 46311 | D13: CI/CD with GitHub Actions [MILESTONE] | E13: Workflows, secrets, artifacts, matrix, schedule, badges. | F13: 1. GitHub Actions - Quickstart [Docs, ~30 min] https://docs.github.com/en/actions/quickstart 2. Playwright - Continuous Integration [Docs, ~30 min] https://playwright.dev/python/docs/ci-intro 3. GitHub Skills - Hello GitHub Actions [Interactive, ~30 min] https://skills.github.com | G13: 1) Workflow: API tests on push, Playwright on PR. 2) Upload HTML report + traces as artifacts. 3) Nightly scheduled run. 4) Add status badge to README. | H13: Projects A (Playwright) and B (API) public on GitHub with green CI | I13: GitHub Actions skeleton for qa-copilot (lint + unit tests) | J13: GitHub Actions
A14: 11 | B14: 3 | C14: =WORKDAY(Overview!$B$4,A14-1) -> 46314 | D14: Prompting for test design | E14: Role, context, constraints, output format; ask AI for assumptions + questions; drive BVA/EP/risk. | F14: 1. Anthropic - Prompt engineering overview [Docs, ~45 min] https://docs.claude.com/en/docs/build-with-claude/prompt-engineering/overview 2. OpenAI - Prompt engineering guide [Docs, ~30 min] https://platform.openai.com/docs/guides/prompt-engineering 3. Prompt Engineering Guide [Guide, ~30 min] https://www.promptingguide.ai | G14: Take 3 real user stories (login, payment, search). 1) Prompt v1 = naive; prompt v2 = role + context + AC + techniques + JSON schema + 'list assumptions'. 2) Compare vs your manual cases: edge cases AI found that you missed, duplicates, hallucinated features. 3) Save best prompt as prompts/testcase_gen.md. | H14: Prompt v1 vs v2 comparison table + saved prompt | I14: prompts/ folder (versioned); output validated against TestCase schema | J14: ChatGPT, Copilot, Claude
A15: 12 | B15: 3 | C15: =WORKDAY(Overview!$B$4,A15-1) -> 46315 | D15: Advanced AI test design | E15: Ambiguity finder, test data generation, risk-based prioritisation, bug writing, reviewing AI output. | F15: 1. Prompt Engineering Guide - techniques (few-shot, CoT, structured output) [Guide, ~45 min] https://www.promptingguide.ai 2. Ministry of Testing - articles & community [Community, ~30 min] https://www.ministryoftesting.com 3. Anthropic - Prompt engineering: use XML/structured output [Docs, ~30 min] https://docs.claude.com/en/docs/build-with-claude/prompt-engineering/overview | G15: 1) Ambiguity finder: requirement -> questions for the BA. 2) Test-data generator (valid/invalid/boundary/unicode/long). 3) Risk prioritiser: AI scores, you override with reasons. 4) Raw notes -> clean bug report. 5) Write a 8-point AI-output review checklist (traceability, duplicates, wrong expected result, invented features...). | H15: Prompt library (5 prompts) + review checklist | I15: Add review-checklist as automated validators in core/ (schema, duplicates, traceability) | J15: ChatGPT, Claude, Copilot
... A28: 25 | B28: 5 | C28: =WORKDAY(Overview!$B$4,A28-1) -> 46332 | D28: Ship & showcase [MILESTONE] | E28: Documentation, demo, portfolio, interview readiness. | F28: 1. Make a README [Guide, ~20 min] https://www.makeareadme.com 2. Choose a License [Guide, ~10 min] https://choosealicense.com 3. Shields.io badges [Tool, ~10 min] https://shields.io 4. Mermaid - architecture diagrams in README [Docs, ~20 min] https://mermaid.js.org | G28: 1) README: architecture diagram, 5-minute setup, demo GIF/video. 2) Docs: plug in your own LLM / Confluence / Jira. 3) Sample outputs + LICENSE. 4) Pin 3 repos on GitHub profile. 5) Update resume/LinkedIn with metrics (time saved, cases generated, bugs found). 6) Final Skills self-rating + 10 mock interview questions. | H28: Public repos A, B, C + Capstone; 1 LinkedIn post | I28: Release v1.0 tag | J28: GitHub, LinkedIn

Sheet Learn From
A1: Where to learn each topic (all free; first item = start here)
A2: Daily rhythm: ~1 hr LEARN from this sheet, then ~2 hrs PRACTICE with the exercise. Links change - if one breaks, search the title.
A3: Day # | B3: Week | C3: Topic | D3: Resource | E3: Type | F3: Est. min | G3: URL
A4: 1 | B4: 1 | C4: ='5-Week Plan'!D4 -> Dev setup + Git & GitHub | D4: Pro Git book - ch.1-3 (basics, branching) | E4: Book/docs | F4: 60 | G4: https://git-scm.com/book/en/v2
A5: 1 | B5: 1 | C5: ='5-Week Plan'!D4 -> Dev setup + Git & GitHub | D5: GitHub Skills - Introduction to GitHub (hands-on) | E5: Interactive | F5: 30 | G5: https://skills.github.com
A6: 1 | B6: 1 | C6: ='5-Week Plan'!D4 -> Dev setup + Git & GitHub | D6: GitHub Docs - Get started | E6: Docs | F6: 20 | G6: https://docs.github.com/en/get-started
A7: 2 | B7: 1 | C7: ='5-Week Plan'!D5 -> Python core for testers | D7: Automate the Boring Stuff - Python basics ch.1-6 | E7: Free book | F7: 90 | G7: https://automatetheboringstuff.com
A8: 2 | B8: 1 | C8: ='5-Week Plan'!D5 -> Python core for testers | D8: Official Python Tutorial (loops, functions, errors) | E8: Docs | F8: 45 | G8: https://docs.python.org/3/tutorial/
A9: 2 | B9: 1 | C9: ='5-Week Plan'!D5 -> Python core for testers | D9: Real Python - beginner articles | E9: Articles | F9: 30 | G9: https://realpython.com
A10: 3 | B10: 1 | C10: ='5-Week Plan'!D6 -> Python OOP, files, JSON/CSV | D10: Python docs - dataclasses | E10: Docs | F10: 30 | G10: https://docs.python.org/3/library/dataclasses.html
A11: 3 | B11: 1 | C11: ='5-Week Plan'!D6 -> Python OOP, files, JSON/CSV | D11: Python docs - json and csv modules | E11: Docs | F11: 30 | G11: https://docs.python.org/3/library/json.html
A12: 3 | B12: 1 | C12: ='5-Week Plan'!D6 -> Python OOP, files, JSON/CSV | D12: Pydantic - getting started | E12: Docs | F12: 30 | G12: https://docs.pydantic.dev
A13: 3 | B13: 1 | C13: ='5-Week Plan'!D6 -> Python OOP, files, JSON/CSV | D13: JSON Schema - Learn | E13: Docs | F13: 30 | G13: https://json-schema.org/learn
A14: 4 | B14: 1 | C14: ='5-Week Plan'!D7 -> SQL for testers | D14: SQLBolt - interactive SQL lessons 1-18 | E14: Interactive | F14: 90 | G14: https://sqlbolt.com
A15: 4 | B15: 1 | C15: ='5-Week Plan'!D7 -> SQL for testers | D15: SQLite - SQL language reference | E15: Docs | F15: 20 | G15: https://sqlite.org/lang.html
A16: 4 | B16: 1 | C16: ='5-Week Plan'!D7 -> SQL for testers | D16: Chinook sample database (practice data) | E16: Dataset | F16: 15 | G16: https://github.com/lerocha/chinook-database
A17: 4 | B17: 1 | C17: ='5-Week Plan'!D7 -> SQL for testers | D17: SQLZoo - extra practice | E17: Interactive | F17: 45 | G17: https://sqlzoo.net
A18: 5 | B18: 1 | C18: ='5-Week Plan'!D8 -> HTTP/REST + Postman | D18: Postman Learning Center - 'Postman 101' | E18: Docs/Video | F18: 60 | G18: https://learning.postman.com
A19: 5 | B19: 1 | C19: ='5-Week Plan'!D8 -> HTTP/REST + Postman | D19: MDN - HTTP overview, methods, status codes | E19: Docs | F19: 45 | G19: https://developer.mozilla.org/en-US/docs/Web/HTTP
A20: 5 | B20: 1 | C20: ='5-Week Plan'!D8 -> HTTP/REST + Postman | D20: Restful-Booker API docs (your practice API) | E20: API docs | F20: 15 | G20: https://restful-booker.herokuapp.com/apidoc/index.html
A21: 6 | B21: 2 | C21: ='5-Week Plan'!D9 -> API automation: Python requests + pytest | D21: Requests - Quickstart | E21: Docs | F21: 30 | G21: https://requests.readthedocs.io
A22: 6 | B22: 2 | C22: ='5-Week Plan'!D9 -> API automation: Python requests + pytest | D22: pytest - Get started + fixtures | E22: Docs | F22: 60 | G22: https://docs.pytest.org
A23: 6 | B23: 2 | C23: ='5-Week Plan'!D9 -> API automation: Python requests + pytest | D23: Real Python - Effective testing with pytest | E23: Article | F23: 30 | G23: https://realpython.com/pytest-python-testing/
A24: 7 | B24: 2 | C24: ='5-Week Plan'!D10 -> pytest advanced + data-driven | D24: pytest - How to parametrize | E24: Docs | F24: 30 | G24: https://docs.pytest.org/en/stable/how-to/parametrize.html
A25: 7 | B25: 2 | C25: ='5-Week Plan'!D10 -> pytest advanced + data-driven | D25: jsonschema validation in Python | E25: Docs | F25: 20 | G25: https://python-jsonschema.readthedocs.io
A26: 7 | B26: 2 | C26: ='5-Week Plan'!D10 -> pytest advanced + data-driven | D26: Allure Report docs | E26: Docs | F26: 30 | G26: https://allurereport.org/docs/
A27: 7 | B27: 2 | C27: ='5-Week Plan'!D10 -> pytest advanced + data-driven | D27: pytest-html | E27: Docs | F27: 15 | G27: https://pytest-html.readthedocs.io
A28: 8 | B28: 2 | C28: ='5-Week Plan'!D11 -> Playwright basics | D28: Playwright Python - Getting started | E28: Docs | F28: 45 | G28: https://playwright.dev/python/docs/intro
A29: 8 | B29: 2 | C29: ='5-Week Plan'!D11 -> Playwright basics | D29: Playwright - Locators | E29: Docs | F29: 30 | G29: https://playwright.dev/python/docs/locators
A30: 8 | B30: 2 | C30: ='5-Week Plan'!D11 -> Playwright basics | D30: Playwright - Trace Viewer | E30: Docs | F30: 20 | G30: https://playwright.dev/python/docs/trace-viewer
A31: 8 | B31: 2 | C31: ='5-Week Plan'!D11 -> Playwright basics | D31: Playwright - Codegen | E31: Docs | F31: 15 | G31: https://playwright.dev/python/docs/codegen
A32: 9 | B32: 2 | C32: ='5-Week Plan'!D12 -> Playwright framework design | D32: Playwright - Page Object Models | E32: Docs | F32: 30 | G32: https://playwright.dev/python/docs/pom
A33: 9 | B33: 2 | C33: ='5-Week Plan'!D12 -> Playwright framework design | D33: Playwright - Authentication (storage_state) | E33: Docs | F33: 20 | G33: https://playwright.dev/python/docs/auth
A34: 9 | B34: 2 | C34: ='5-Week Plan'!D12 -> Playwright framework design | D34: Playwright - API testing | E34: Docs | F34: 30 | G34: https://playwright.dev/python/docs/api-testing
A35: 10 | B35: 2 | C35: ='5-Week Plan'!D13 -> CI/CD with GitHub Actions [MILESTONE] | D35: GitHub Actions - Quickstart | E35: Docs | F35: 30 | G35: https://docs.github.com/en/actions/quickstart
A36: 10 | B36: 2 | C36: ='5-Week Plan'!D13 -> CI/CD with GitHub Actions [MILESTONE] | D36: Playwright - Continuous Integration | E36: Docs | F36: 30 | G36: https://playwright.dev/python/docs/ci-intro
A37: 10 | B37: 2 | C37: ='5-Week Plan'!D13 -> CI/CD with GitHub Actions [MILESTONE] | D37: GitHub Skills - Hello GitHub Actions | E37: Interactive | F37: 30 | G37: https://skills.github.com
A38: 11 | B38: 3 | C38: ='5-Week Plan'!D14 -> Prompting for test design | D38: Anthropic - Prompt engineering overview | E38: Docs | F38: 45 | G38: https://docs.claude.com/en/docs/build-with-claude/prompt-engineering/overview
A39: 11 | B39: 3 | C39: ='5-Week Plan'!D14 -> Prompting for test design | D39: OpenAI - Prompt engineering guide | E39: Docs | F39: 30 | G39: https://platform.openai.com/docs/guides/prompt-engineering
A40: 11 | B40: 3 | C40: ='5-Week Plan'!D14 -> Prompting for test design | D40: Prompt Engineering Guide | E40: Guide | F40: 30 | G40: https://www.promptingguide.ai
...

Sheet Tracker
A1: Daily tracker
A2: EXAMPLE of a filled row -> Status: Done | Actual start: 05-Oct-2026 | Actual hrs: 3.5 | Evidence: https://github.com/you/ai-qa-journey/pull/1 | Confidence: 4 | Notes: Rebase confused me, redo conflict drill.
A3: Day # | B3: Week | C3: Planned date | D3: Topic | E3: Planned hrs | F3: Status | G3: Actual start | H3: Actual hrs | I3: Evidence link (GitHub/commit/page) | J3: Confidence (1-5) | K3: Notes / blockers
A4: ='5-Week Plan'!A4 -> 1 | B4: ='5-Week Plan'!B4 -> 1 | C4: ='5-Week Plan'!C4 -> 46300 | D4: ='5-Week Plan'!D4 -> Dev setup + Git & GitHub | E4: =Overview!$B$5 -> 3 | F4: Done | G4: 46316.618 | H4: 3 | I4: https://github.com/AliHassan-creator/ai-qa-journey/pull/2 | J4: 4 | K4: N/A
A5: ='5-Week Plan'!A5 -> 2 | B5: ='5-Week Plan'!B5 -> 1 | C5: ='5-Week Plan'!C5 -> 46301 | D5: ='5-Week Plan'!D5 -> Python core for testers | E5: =Overview!$B$5 -> 3 | F5: Done | G5: 46316.744 | H5: 3 | I5: Done | J5: 5 | K5: N/A
A6: ='5-Week Plan'!A6 -> 3 | B6: ='5-Week Plan'!B6 -> 1 | C6: ='5-Week Plan'!C6 -> 46302 | D6: ='5-Week Plan'!D6 -> Python OOP, files, JSON/CSV | E6: =Overview!$B$5 -> 3 | F6: Done | G6: 46317.663 | H6: 1 | I6: Done | J6: 4 | K6: N/A
A7: ='5-Week Plan'!A7 -> 4 | B7: ='5-Week Plan'!B7 -> 1 | C7: ='5-Week Plan'!C7 -> 46303 | D7: ='5-Week Plan'!D7 -> SQL for testers | E7: =Overview!$B$5 -> 3 | F7: Done | G7: 46317.663 | H7: 2.5 | I7: Done | J7: 4 | K7: N/A
A8: ='5-Week Plan'!A8 -> 5 | B8: ='5-Week Plan'!B8 -> 1 | C8: ='5-Week Plan'!C8 -> 46304 | D8: ='5-Week Plan'!D8 -> HTTP/REST + Postman | E8: =Overview!$B$5 -> 3 | F8: Done | G8: 46318.663 | H8: 2 | I8: Done | J8: 4 | K8: N/A
A9: ='5-Week Plan'!A9 -> 6 | B9: ='5-Week Plan'!B9 -> 2 | C9: ='5-Week Plan'!C9 -> 46307 | D9: ='5-Week Plan'!D9 -> API automation: Python requests + pytest | E9: =Overview!$B$5 -> 3 | F9: Done | G9: 46318.663 | H9: 2.5 | I9: Done | J9: 5 | K9: N/A
A10: ='5-Week Plan'!A10 -> 7 | B10: ='5-Week Plan'!B10 -> 2 | C10: ='5-Week Plan'!C10 -> 46308 | D10: ='5-Week Plan'!D10 -> pytest advanced + data-driven | E10: =Overview!$B$5 -> 3 | F10: In Progress | G10: 46321.58
A11: ='5-Week Plan'!A11 -> 8 | B11: ='5-Week Plan'!B11 -> 2 | C11: ='5-Week Plan'!C11 -> 46309 | D11: ='5-Week Plan'!D11 -> Playwright basics | E11: =Overview!$B$5 -> 3 | F11: Not Started
A12: ='5-Week Plan'!A12 -> 9 | B12: ='5-Week Plan'!B12 -> 2 | C12: ='5-Week Plan'!C12 -> 46310 | D12: ='5-Week Plan'!D12 -> Playwright framework design | E12: =Overview!$B$5 -> 3 | F12: Not Started
A13: ='5-Week Plan'!A13 -> 10 | B13: ='5-Week Plan'!B13 -> 2 | C13: ='5-Week Plan'!C13 -> 46311 | D13: ='5-Week Plan'!D13 -> CI/CD with GitHub Actions [MILESTONE] | E13: =Overview!$B$5 -> 3 | F13: Not Started
A14: ='5-Week Plan'!A14 -> 11 | B14: ='5-Week Plan'!B14 -> 3 | C14: ='5-Week Plan'!C14 -> 46314 | D14: ='5-Week Plan'!D14 -> Prompting for test design | E14: =Overview!$B$5 -> 3 | F14: Not Started
A15: ='5-Week Plan'!A15 -> 12 | B15: ='5-Week Plan'!B15 -> 3 | C15: ='5-Week Plan'!C15 -> 46315 | D15: ='5-Week Plan'!D15 -> Advanced AI test design | E15: =Overview!$B$5 -> 3 | F15: Not Started
A16: ='5-Week Plan'!A16 -> 13 | B16: ='5-Week Plan'!B16 -> 3 | C16: ='5-Week Plan'!C16 -> 46316 | D16: ='5-Week Plan'!D16 -> Coding assistants: Copilot & Claude Code | E16: =Overview!$B$5 -> 3 | F16: Not Started
A17: ='5-Week Plan'!A17 -> 14 | B17: ='5-Week Plan'!B17 -> 3 | C17: ='5-Week Plan'!C17 -> 46317 | D17: ='5-Week Plan'!D17 -> Skills, agents, slash commands | E17: =Overview!$B$5 -> 3 | F17: Not Started
A18: ='5-Week Plan'!A18 -> 15 | B18: ='5-Week Plan'!B18 -> 3 | C18: ='5-Week Plan'!C18 -> 46318 | D18: ='5-Week Plan'!D18 -> AI-powered testing tools & self-healing | E18: =Overview!$B$5 -> 3 | F18: Not Started
A19: ='5-Week Plan'!A19 -> 16 | B19: ='5-Week Plan'!B19 -> 4 | C19: ='5-Week Plan'!C19 -> 46321 | D19: ='5-Week Plan'!D19 -> MCP fundamentals + Playwright MCP | E19: =Overview!$B$5 -> 3 | F19: Not Started
A20: ='5-Week Plan'!A20 -> 17 | B20: ='5-Week Plan'!B20 -> 4 | C20: ='5-Week Plan'!C20 -> 46322 | D20: ='5-Week Plan'!D20 -> Read stories & PRs via MCP (GitHub/Jira) | E20: =Overview!$B$5 -> 3 | F20: Not Started
A21: ='5-Week Plan'!A21 -> 18 | B21: ='5-Week Plan'!B21 -> 4 | C21: ='5-Week Plan'!C21 -> 46323 | D21: ='5-Week Plan'!D21 -> Write test cases to Confluence | E21: =Overview!$B$5 -> 3 | F21: Not Started
A22: ='5-Week Plan'!A22 -> 19 | B22: ='5-Week Plan'!B22 -> 4 | C22: ='5-Week Plan'!C22 -> 46324 | D22: ='5-Week Plan'!D22 -> Test case -> automation -> bug | E22: =Overview!$B$5 -> 3 | F22: Not Started
... A28: ='5-Week Plan'!A28 -> 25 | B28: ='5-Week Plan'!B28 -> 5 | C28: ='5-Week Plan'!C28 -> 46332 | D28: ='5-Week Plan'!D28 -> Ship & showcase [MILESTONE] | E28: =Overview!$B$5 -> 3 | F28: Not Started

Sheet Dashboard
A1: Progress dashboard
A2: All formulas - driven by the Tracker sheet.
A3: Week | B3: Days planned | C3: Days done | D3: % complete | E3: Planned hrs | F3: Actual hrs | G3: Days blocked
A4: Week 1 - Code Like a Tester | B4: =COUNTIF(Tracker!$B$4:$B$28,1) -> 5 | C4: =COUNTIFS(Tracker!$B$4:$B$28,1,Tracker!$F$4:$F$28,"Done") -> 5 | D4: =IF(B4=0,0,C4/B4) -> 1 | E4: =SUMIF(Tracker!$B$4:$B$28,1,Tracker!$E$4:$E$28) -> 15 | F4: =SUMIF(Tracker!$B$4:$B$28,1,Tracker!$H$4:$H$28) -> 11.5 | G4: =COUNTIFS(Tracker!$B$4:$B$28,1,Tracker!$F$4:$F$28,"Blocked") -> 0
A5: Week 2 - Automate (without AI first) | B5: =COUNTIF(Tracker!$B$4:$B$28,2) -> 5 | C5: =COUNTIFS(Tracker!$B$4:$B$28,2,Tracker!$F$4:$F$28,"Done") -> 1 | D5: =IF(B5=0,0,C5/B5) -> 0.2 | E5: =SUMIF(Tracker!$B$4:$B$28,2,Tracker!$E$4:$E$28) -> 15 | F5: =SUMIF(Tracker!$B$4:$B$28,2,Tracker!$H$4:$H$28) -> 2.5 | G5: =COUNTIFS(Tracker!$B$4:$B$28,2,Tracker!$F$4:$F$28,"Blocked") -> 0
A6: Week 3 - Use AI to Test Faster | B6: =COUNTIF(Tracker!$B$4:$B$28,3) -> 5 | C6: =COUNTIFS(Tracker!$B$4:$B$28,3,Tracker!$F$4:$F$28,"Done") -> 0 | D6: =IF(B6=0,0,C6/B6) -> 0 | E6: =SUMIF(Tracker!$B$4:$B$28,3,Tracker!$E$4:$E$28) -> 15 | F6: =SUMIF(Tracker!$B$4:$B$28,3,Tracker!$H$4:$H$28) -> 0 | G6: =COUNTIFS(Tracker!$B$4:$B$28,3,Tracker!$F$4:$F$28,"Blocked") -> 0
A7: Week 4 - MCP & Integrations | B7: =COUNTIF(Tracker!$B$4:$B$28,4) -> 5 | C7: =COUNTIFS(Tracker!$B$4:$B$28,4,Tracker!$F$4:$F$28,"Done") -> 0 | D7: =IF(B7=0,0,C7/B7) -> 0 | E7: =SUMIF(Tracker!$B$4:$B$28,4,Tracker!$E$4:$E$28) -> 15 | F7: =SUMIF(Tracker!$B$4:$B$28,4,Tracker!$H$4:$H$28) -> 0 | G7: =COUNTIFS(Tracker!$B$4:$B$28,4,Tracker!$F$4:$F$28,"Blocked") -> 0
A8: Week 5 - Test AI Systems + Capstone | B8: =COUNTIF(Tracker!$B$4:$B$28,5) -> 5 | C8: =COUNTIFS(Tracker!$B$4:$B$28,5,Tracker!$F$4:$F$28,"Done") -> 0 | D8: =IF(B8=0,0,C8/B8) -> 0 | E8: =SUMIF(Tracker!$B$4:$B$28,5,Tracker!$E$4:$E$28) -> 15 | F8: =SUMIF(Tracker!$B$4:$B$28,5,Tracker!$H$4:$H$28) -> 0 | G8: =COUNTIFS(Tracker!$B$4:$B$28,5,Tracker!$F$4:$F$28,"Blocked") -> 0
A9: (Total row below)
A10: TOTAL | B10: =SUM(B4:B8) -> 25 | C10: =SUM(C4:C8) -> 6 | D10: =IF(B10=0,0,C10/B10) -> 0.24 | E10: =SUM(E4:E8) -> 75 | F10: =SUM(F4:F8) -> 14 | G10: =SUM(G4:G8) -> 0
A12: Days behind schedule (planned date passed, not Done) | D12: =COUNTIFS(Tracker!$C$4:$C$28,"<"&TODAY(),Tracker!$F$4:$F$28,"<>Done") -> 9
A13: Average confidence (1-5) of completed days | D13: =IFERROR(AVERAGEIF(Tracker!$J$4:$J$28,">0"),0) -> 4.3333333
A14: Hours variance (Actual - Planned, for days with hours logged) | D14: =F10-SUMIF(Tracker!$H$4:$H$28,">0",Tracker!$E$4:$E$28) -> -4
A16: Milestones: Day 10 = Projects A+B live in CI | Day 15 = AI skills/agents built | Day 20 = MCP pipeline working | Day 25 = Capstone + Project C shipped

Sheet Capstone
A1: Capstone: QA-Copilot - a reusable AI-QA toolkit anyone can run
A2: Built incrementally (see 'Capstone increment' column in the plan). Provider-agnostic, config-driven, human-in-the-loop.
A3: # | B3: Module | C3: What it does | D3: Input | E3: Output | F3: How AI is used | G3: Guardrails | H3: Built in | I3: Done when (acceptance criteria)
A4: 1 | B4: Core schema & validators | C4: Canonical TestCase/Bug schema; BVA/EP helpers; validators for duplicates, traceability, schema. | D4: - | E4: TestCase JSON, validation report | F4: None - deterministic checks of AI output | G4: Reject output that fails schema | H4: Wk1-3 | I4: Invalid/duplicate/untraceable cases are rejected with reasons; 10+ unit tests
A5: 2 | B5: PR Analyzer | C5: Reads a PR diff + changed files + callers; finds impacted areas and regression risk. | D5: PR URL or git diff | E5: Impact summary + risk score | F5: LLM summarises change + reasons about risk using code context | G5: PR text treated as UNTRUSTED data (injection-safe) | H5: Wk3-4 | I5: Given 3 sample PRs, lists impacted modules matching your manual review >= 80%
A6: 3 | B6: Test Case Generator | C6: Creates functional, negative, boundary, and edge cases from story/AC/PR. | D6: Story, AC, PR analysis | E6: TestCase JSON/CSV/Markdown | F6: Prompt templates with BVA/EP/risk rules; asks clarifying questions | G6: Schema-validated; max cases cap; assumptions listed | H6: Wk3-4 | I6: Covers all AC; all BVA points present; 0 invented features on golden set
A7: 4 | B7: Confluence Publisher | C7: Publishes/updates test cases as a Confluence page with traceability. | D7: TestCase JSON | E7: Confluence page URL | F7: AI formats/links; MCP or REST API does the write | G7: Dry-run default; approval flag; idempotent update (no duplicates) | H7: Wk4 | I7: Re-running updates same page; dry-run shows diff only
A8: 5 | B8: Automation Generator | C8: Turns approved test cases into Playwright (pytest) code following project conventions. | D8: Approved TestCase JSON + CLAUDE.md rules | E8: Test files in tests/generated/ | F8: LLM code-gen with conventions; lint + dry-run executes before saving | G8: Code must pass lint + run once; no sleeps; no secrets | H8: Wk4 | I8: 80%+ of generated tests run green on demo app without manual edits
A9: 6 | B9: Runner & Healer | C9: Runs tests, collects results/traces; proposes locator fixes. | D9: Test folder | E9: Result JSON, traces | F9: AI proposes a patch for broken locators | G9: Patch is a reviewable diff; never auto-merged | H9: Wk2-4 | I9: Broken locator -> patch proposal; false-heal rate tracked
A10: 7 | B10: Bug Reporter | C10: Classifies failures (product/test/env/flaky) and drafts bugs with evidence. | D10: Failure + trace + screenshot + logs | E10: GitHub/Jira issue draft -> issue | F10: LLM triage + bug writing | G10: Approval before create; duplicate check by title/hash | H10: Wk4 | I10: 3 seeded bugs found, classified correctly, issues created with attachments
A11: 8 | B11: AI Eval & Security Harness | C11: Dogfoods: scores Copilot outputs against golden data; runs injection/hallucination tests. | D11: golden.jsonl, attack suite | E11: Score report, pass/fail threshold | F11: LLM-as-judge (temp 0) + deterministic checks | G11: Run in CI; fail build below threshold | H11: Wk5 | I11: CI fails when quality drops; injected PR does not change behaviour
A12: 9 | B12: CLI, config & packaging | C12: Single entry point for everyone: qa-copilot run --pr <url> --dry-run | D12: config.yaml | E12: Reports | F12: Provider adapters (Claude / OpenAI / Copilot / local) | G12: No secrets in repo; .env.example; sample demo repo | H12: Wk5 | I12: New user runs demo in 5 minutes via README or Docker
A15: Flow
A16: PR / Story -> PR Analyzer -> Test Case Generator -> [human review] -> Confluence Publisher -> Automation Generator -> Runner/Healer -> Bug Reporter -> Report (Eval & Security harness guards every AI step)
A18: Design principles so that ANYONE can use it
A19: - Config-driven: no hardcoded URLs, tokens, models. Everything in config.yaml + .env.
A20: - Provider-agnostic LLM adapter (swap Claude/OpenAI/Copilot/local).
A21: - Human-in-the-loop: dry-run by default; every write (Confluence, Jira, git) needs an explicit approval flag.
A22: - Schema-first: all AI output is JSON validated before use.
A23: - Demo mode: ships with a sample app + sample PRs so a new user sees results without setup.
A24: - Treat external text (PRs, tickets, docs) as untrusted - prompt-injection tests are part of CI.

Sheet Portfolio
A1: GitHub portfolio checklist
A3: Project | B3: Item | C3: Status | D3: Link / notes
A4: A - Playwright UI project | B4: POM structure, 8+ tests, storage_state login reuse | C4: Not Started
A5: A - Playwright UI project | B5: GitHub Actions CI green + report/trace artifacts | C5: Not Started
A6: A - Playwright UI project | B6: README with how-to-run + badge | C6: Not Started
A7: B - API test suite | B7: CRUD + negative + data-driven tests, schema validation | C7: Not Started
A8: B - API test suite | B8: Smoke/regression markers + HTML report | C8: Not Started
A9: B - API test suite | B9: CI green + Postman collection included | C9: Not Started
A10: C - AI system testing | B10: Golden dataset (30-50 cases) + evaluator | C10: Not Started
A11: C - AI system testing | B11: Hallucination + inconsistency + bias probes | C11: Not Started
A12: C - AI system testing | B12: 25 prompt-injection/leak cases, mapped to OWASP LLM Top 10 | C12: Not Started
A13: Capstone - QA-Copilot | B13: PR -> test cases -> Confluence flow works (dry-run + real) | C13: Not Started
A14: Capstone - QA-Copilot | B14: Test cases -> Playwright code -> run -> bug draft flow works | C14: Not Started
A15: Capstone - QA-Copilot | B15: README, demo video/GIF, Docker, config.yaml, LICENSE | C15: Not Started
A16: Capstone - QA-Copilot | B16: Eval/security harness in CI | C16: Not Started
A18: Portfolio completion | C18: =COUNTIF(C4:C16,"Done")/COUNTA(B4:B16) -> 0

Sheet Skills
A1: Skills self-assessment (1 = never done, 5 = can teach it)
A2: Rate 'Before' on Day 1, 'After' on Day 25. Example row: Git branching | Before 2 | After 4.
A3: Skill | B3: Area | C3: Before (1-5) | D3: After (1-5) | E3: Gain
A4: Git/GitHub workflow | B4: Coding | E4: =IF(OR(C4="",D4=""),"",D4-C4)
A5: Python scripting | B5: Coding | E5: =IF(OR(C5="",D5=""),"",D5-C5)
A6: SQL validation queries | B6: Coding | E6: =IF(OR(C6="",D6=""),"",D6-C6)
A7: REST/HTTP & Postman | B7: Coding | E7: =IF(OR(C7="",D7=""),"",D7-C7)
A8: API automation (pytest) | B8: Automation | E8: =IF(OR(C8="",D8=""),"",D8-C8)
A9: Playwright UI automation | B9: Automation | E9: =IF(OR(C9="",D9=""),"",D9-C9)
A10: CI with GitHub Actions | B10: Automation | E10: =IF(OR(C10="",D10=""),"",D10-C10)
A11: Prompting for test design | B11: AI for QA | E11: =IF(OR(C11="",D11=""),"",D11-C11)
A12: Coding assistants (Copilot/Claude Code) | B12: AI for QA | E12: =IF(OR(C12="",D12=""),"",D12-C12)
A13: Skills / agents / commands | B13: AI for QA | E13: =IF(OR(C13="",D13=""),"",D13-C13)
A14: Self-healing & AI test tools | B14: AI for QA | E14: =IF(OR(C14="",D14=""),"",D14-C14)
A15: MCP usage (Jira/Confluence/Playwright) | B15: MCP | E15: =IF(OR(C15="",D15=""),"",D15-C15)
... A19: Prompt injection / AI security testing | B19: Testing AI | E19: =IF(OR(C19="",D19=""),"",D19-C19)
A21: Average | C21: =IFERROR(AVERAGE(C4:C19),0) -> 0 | D21: =IFERROR(AVERAGE(D4:D19),0) -> 0 | E21: =IFERROR(AVERAGE(E4:E19),0) -> 0

Sheet Practice Sites
A1: Practice sites & docs (verify links - sites change)
A3: Use | B3: Resource | C3: URL
A4: UI practice | B4: Sauce Demo (has 'problem_user' for seeded bugs) | C4: https://www.saucedemo.com
A5: API practice | B5: Restful-Booker | C5: https://restful-booker.herokuapp.com
A6: Playwright docs | B6: Playwright | C6: https://playwright.dev
A7: MCP concepts | B7: Model Context Protocol | C7: https://modelcontextprotocol.io
A8: Claude Code docs | B8: Claude Code overview | C8: https://docs.claude.com/en/docs/claude-code/overview
A9: Prompt injection practice | B9: Gandalf (Lakera) | C9: https://gandalf.lakera.ai
A10: AI security checklist | B10: OWASP Top 10 for LLM Applications | C10: https://owasp.org/www-project-top-10-for-large-language-model-applications/
A11: LLM evals | B11: promptfoo | C11: https://www.promptfoo.dev
A12: Jira/Confluence | B12: Atlassian free cloud plan | C12: https://www.atlassian.com/software/jira/free
